<?xml version="1.0" ?>
<!-- =================================================================================== -->
<!-- |    This document was autogenerated by xacro from robot_base.urdf.xacro          | -->
<!-- |    EDITING THIS FILE BY HAND IS NOT RECOMMENDED                                 | -->
<!-- =================================================================================== -->
<robot name="mobile_base_robot">
  <!-- Color Definitions for Rviz -->
  <material name="burlywood">
    <color rgba="0.87 0.72 0.53 1.0"/>
  </material>
  <material name="dark_blue">
    <color rgba="0.0 0.0 0.7 1.0"/>
  </material>
  <material name="light_blue">
    <color rgba="0.0 0.3 1.0 1.0"/>
  </material>
  <material name="light_green">
    <color rgba="0.0 1.0 0.0 1.0"/>
  </material>
  <material name="red">
    <color rgba="1.0 0.0 0.0 1.0"/>
  </material>
  <material name="orange">
    <color rgba="1.0 0.6 0.0 1.0"/>
  </material>
  <material name="yellow">
    <color rgba="1.0 1.0 0.0 1.0"/>
  </material>
  <material name="black">
    <color rgba="0.0 0.0 0.0 1.0"/>
  </material>
  <material name="white">
    <color rgba="1.0 1.0 1.0 1.0"/>
  </material>
  <material name="dark_gray">
    <color rgba="0.4 0.4 0.4 1.0"/>
  </material>
  <material name="light_gray">
    <color rgba="0.7 0.7 0.7 1.0"/>
  </material>
  <material name="plexiglass">
    <color rgba="1.0 1.0 1.0 0.2"/>
  </material>
  <material name="transparent">
    <color rgba="1.0 1.0 1.0 0.0"/>
  </material>
  <gazebo reference="front_left_wheel">
    <mu1 value="1.0"/>
    <mu2 value="1.0"/>
    <kp value="10000000.0"/>
    <kd value="1.0"/>
    <fdir1 value="1 0 0"/>
    <material>Gazebo/DarkGrey</material>
  </gazebo>
  <gazebo reference="front_right_wheel">
    <mu1 value="1.0"/>
    <mu2 value="1.0"/>
    <kp value="10000000.0"/>
    <kd value="1.0"/>
    <fdir1 value="1 0 0"/>
    <material>Gazebo/DarkGrey</material>
  </gazebo>
  <gazebo reference="rear_left_wheel">
    <mu1 value="1.0"/>
    <mu2 value="1.0"/>
    <kp value="10000000.0"/>
    <kd value="1.0"/>
    <fdir1 value="1 0 0"/>
    <material>Gazebo/DarkGrey</material>
  </gazebo>
  <gazebo reference="rear_right_wheel">
    <mu1 value="1.0"/>
    <mu2 value="1.0"/>
    <kp value="10000000.0"/>
    <kd value="1.0"/>
    <fdir1 value="1 0 0"/>
    <material>Gazebo/DarkGrey</material>
  </gazebo>
  <!-- Diff drive controller -->
  <gazebo>
    <plugin filename="libgazebo_ros_diff_drive.so" name="diff_drive">
      <!-- Wheel information -->
      <left_joint>front_left_wheel_joint</left_joint>
      <right_joint>front_right_wheel_joint</right_joint>
      <!-- kinematics -->
      <wheel_separation>0.5</wheel_separation>
      <wheel_diameter>0.2</wheel_diameter>
      <!-- Wheel limits -->
      <max_wheel_torque>10</max_wheel_torque>
      <max_wheel_acceleration>2.8</max_wheel_acceleration>
      <!-- Output -->
      <odometry_frame>odom</odometry_frame>
      <robot_base_frame>base_link</robot_base_frame>
      <publish_odom>true</publish_odom>
      <publish_odom_tf>true</publish_odom_tf>
      <publish_wheel_tf>true</publish_wheel_tf>
    </plugin>
  </gazebo>
  <!-- Lidar sensor -->
  <gazebo reference="lidar_sensor_ray_link">
    <sensor name="laser" type="ray">
      <pose>0 0 0 0 0 0</pose>
      <always_on>true</always_on>
      <visualize>true</visualize>
      <update_rate>10</update_rate>
      <ray>
        <scan>
          <horizontal>
            <samples>360</samples>
            <min_angle>-1.14</min_angle>
            <max_angle>1.14</max_angle>
          </horizontal>
        </scan>
        <range>
          <resolution>1.0</resolution>
          <min>0.3</min>
          <max>12</max>
        </range>
      </ray>
      <plugin filename="libgazebo_ros_ray_sensor.so" name="laser_controller">
        <ros>
          <argument>~/out:=scan</argument>
        </ros>
        <output_type>sensor_msgs/LaserScan</output_type>
        <frame_name>lidar_sensor_link</frame_name>
      </plugin>
    </sensor>
  </gazebo>
  <!-- 3D depth camera - Orbbec Astra Camera -->
  <gazebo reference="depth_camera_link">
    <!-- The camera type has to be depth not camera -->
    <sensor name="camera" type="depth">
      <pose>0 0 0 0 0 0</pose>
      <visualize>true</visualize>
      <update_rate>10</update_rate>
      <camera>
        <horizontal_fov>1.089</horizontal_fov>
        <image>
          <!-- BGR not RGB like for the camera -->
          <format>B8G8R8</format>
          <width>640</width>
          <height>480</height>
        </image>
        <clip>
          <near>0.03</near>
          <far>12.0</far>
        </clip>
      </camera>
      <plugin filename="libgazebo_ros_camera.so" name="depth_camera_controller">
        <frame_name>camera_link_optical</frame_name>
        <min_depth>0.1</min_depth>
        <max_depth>100.0</max_depth>
      </plugin>
    </sensor>
  </gazebo>
  <ros2_control name="GazeboSystem" type="system">
    <hardware>
      <plugin>gazebo_ros2_control/GazeboSystem</plugin>
    </hardware>
    <!-- Front wheel joints -->
    <joint name="front_left_wheel_joint">
      <command_interface name="velocity">
        <param name="min">-10</param>
        <param name="max">10</param>
      </command_interface>
      <state_interface name="velocity"/>
      <state_interface name="position"/>
    </joint>
    <joint name="front_right_wheel_joint">
      <command_interface name="velocity">
        <param name="min">-10</param>
        <param name="max">10</param>
      </command_interface>
      <state_interface name="velocity"/>
      <state_interface name="position"/>
    </joint>
  </ros2_control>
  <gazebo>
    <plugin filename="libgazebo_ros2_control.so" name="gazebo_ros2_control">
      <parameters>/media/mikelap/DATA/GitRepos/robotics/robot_ws/src/mobile_manipulator_ws/install/mobile_base_bringup/share/mobile_base_bringup/config/2whl_driven_control.yaml</parameters>
    </plugin>
  </gazebo>
  <!--######################################################################-->
  <link name="base_link">
    <visual>
      <origin rpy="0 0 0" xyz="0 0 0"/>
      <geometry>
        <mesh filename="package://mobile_base_description/meshes/robot_base.dae"/>
      </geometry>
      <material name="orange"/>
    </visual>
    <collision>
      <origin rpy="0 0 0" xyz="0 0 0"/>
      <geometry>
        <mesh filename="package://mobile_base_description/meshes/robot_base.stl"/>
      </geometry>
    </collision>
    <inertial>
      <mass value="47.873"/>
      <inertia ixx="0.7978833333333334" ixy="0.0" ixz="0.0" iyy="1.8451052083333332" iyz="0.0" izz="2.323835208333333"/>
    </inertial>
  </link>
  <joint name="front_left_wheel_joint" type="continuous">
    <axis xyz="0 1 0"/>
    <parent link="base_link"/>
    <child link="front_left_wheel"/>
    <origin rpy="0 0 0" xyz="0.220 0.26 0"/>
  </joint>
  <link name="front_left_wheel">
    <visual>
      <origin rpy="0 0 0" xyz="0 0 0"/>
      <geometry>
        <mesh filename="package://mobile_base_description/meshes/wheel.dae"/>
      </geometry>
      <materia name="dark_gray"/>
    </visual>
    <collision>
      <origin rpy="0 0 0" xyz="0 0 0"/>
      <geometry>
        <mesh filename="package://mobile_base_description/meshes/wheel.stl"/>
      </geometry>
    </collision>
    <inertial>
      <mass value="2.6578"/>
      <inertia ixx="0.020968048649999998" ixy="0.0" ixz="0.0" iyy="0.020968048649999998" iyz="0.0" izz="0.0361793025"/>
    </inertial>
  </link>
  <joint name="front_right_wheel_joint" type="continuous">
    <axis xyz="0 1 0"/>
    <parent link="base_link"/>
    <child link="front_right_wheel"/>
    <origin rpy="0 0 0" xyz="0.220 -0.26 0"/>
  </joint>
  <link name="front_right_wheel">
    <visual>
      <origin rpy="0 0 0" xyz="0 0 0"/>
      <geometry>
        <mesh filename="package://mobile_base_description/meshes/wheel.dae"/>
      </geometry>
      <materia name="dark_gray"/>
    </visual>
    <collision>
      <origin rpy="0 0 0" xyz="0 0 0"/>
      <geometry>
        <mesh filename="package://mobile_base_description/meshes/wheel.stl"/>
      </geometry>
    </collision>
    <inertial>
      <mass value="2.6578"/>
      <inertia ixx="0.020968048649999998" ixy="0.0" ixz="0.0" iyy="0.020968048649999998" iyz="0.0" izz="0.0361793025"/>
    </inertial>
  </link>
  <joint name="rear_left_wheel_joint" type="continuous">
    <axis xyz="0 1 0"/>
    <parent link="base_link"/>
    <child link="rear_left_wheel"/>
    <origin rpy="0 0 0" xyz="-0.220 0.26 0"/>
  </joint>
  <link name="rear_left_wheel">
    <visual>
      <origin rpy="0 0 0" xyz="0 0 0"/>
      <geometry>
        <mesh filename="package://mobile_base_description/meshes/wheel.dae"/>
      </geometry>
      <materia name="dark_gray"/>
    </visual>
    <collision>
      <origin rpy="0 0 0" xyz="0 0 0"/>
      <geometry>
        <mesh filename="package://mobile_base_description/meshes/wheel.stl"/>
      </geometry>
    </collision>
    <inertial>
      <mass value="2.6578"/>
      <inertia ixx="0.020968048649999998" ixy="0.0" ixz="0.0" iyy="0.020968048649999998" iyz="0.0" izz="0.0361793025"/>
    </inertial>
  </link>
  <joint name="rear_right_wheel_joint" type="continuous">
    <axis xyz="0 1 0"/>
    <parent link="base_link"/>
    <child link="rear_right_wheel"/>
    <origin rpy="0 0 0" xyz="-0.220 -0.26 0"/>
  </joint>
  <link name="rear_right_wheel">
    <visual>
      <origin rpy="0 0 0" xyz="0 0 0"/>
      <geometry>
        <mesh filename="package://mobile_base_description/meshes/wheel.dae"/>
      </geometry>
      <materia name="dark_gray"/>
    </visual>
    <collision>
      <origin rpy="0 0 0" xyz="0 0 0"/>
      <geometry>
        <mesh filename="package://mobile_base_description/meshes/wheel.stl"/>
      </geometry>
    </collision>
    <inertial>
      <mass value="2.6578"/>
      <inertia ixx="0.020968048649999998" ixy="0.0" ixz="0.0" iyy="0.020968048649999998" iyz="0.0" izz="0.0361793025"/>
    </inertial>
  </link>
  <joint name="lidar_sensor_joint" type="fixed">
    <parent link="base_link"/>
    <child link="lidar_sensor_link"/>
    <origin rpy="0 0 0" xyz="0.25 0 0.15"/>
  </joint>
  <link name="lidar_sensor_link">
    <visual>
      <origin rpy="0.0 0.0 0.0" xyz="0.0 0.0 0.0"/>
      <geometry>
        <mesh filename="package://mobile_base_description/meshes/rplidar_a1.dae"/>
      </geometry>
    </visual>
    <collision>
      <origin rpy="0.0 0.0 0.0" xyz="0.0 0.0 0.0"/>
      <geometry>
        <mesh filename="package://mobile_base_description/meshes/rplidar_a1.stl"/>
      </geometry>
    </collision>
    <inertial>
      <mass value="0.363"/>
      <inertia ixx="0.0004782999924999999" ixy="0.0" ixz="0.0" iyy="0.0006924454900000001" iyz="0.0" izz="0.0008083045025"/>
    </inertial>
  </link>
  <!-- Ray link to move the ray on the z-axis. -->
  <joint name="lidar_sensor_ray_joint" type="fixed">
    <parent link="lidar_sensor_link"/>
    <child link="lidar_sensor_ray_link"/>
    <origin rpy="0 0 0" xyz="0 0 0.01"/>
  </joint>
  <link name="lidar_sensor_ray_link">
    <visual>
      <origin rpy="0 0 0" xyz="0 0 0"/>
      <geometry>
        <box size="0.01 0.01 0.01"/>
      </geometry>
      <material name="transparent"/>
    </visual>
    <collision>
      <origin rpy="0 0 0" xyz="0 0 0"/>
      <geometry>
        <box size="0.01 0.01 0.01"/>
      </geometry>
    </collision>
  </link>
  <joint name="lidar_case_joint" type="fixed">
    <parent link="base_link"/>
    <child link="lidar_case_link"/>
    <origin rpy="0 0 0" xyz="0.235 0 0.15"/>
  </joint>
  <link name="lidar_case_link">
    <visual>
      <origin rpy="0 0 0" xyz="0 0 0"/>
      <geometry>
        <mesh filename="package://mobile_base_description/meshes/lidar_case.dae"/>
      </geometry>
    </visual>
    <collision>
      <origin rpy="0 0 0" xyz="0 0 0"/>
      <geometry>
        <mesh filename="package://mobile_base_description/meshes/lidar_case.stl"/>
      </geometry>
    </collision>
    <inertial>
      <mass value="0.2"/>
      <inertia ixx="0.0008016666666666667" ixy="0.0" ixz="0.0" iyy="0.00027" iyz="0.0" izz="0.0008016666666666667"/>
    </inertial>
  </link>
  <!-- Mounting point -->
  <joint name="depth_camera_joint" type="fixed">
    <parent link="lidar_case_link"/>
    <child link="depth_camera_link"/>
    <origin rpy="0 0 0" xyz="0.01 0 0.11"/>
  </joint>
  <link name="depth_camera_link">
    <visual>
      <origin rpy="0 0 0" xyz="0 0 0"/>
      <geometry>
        <mesh filename="package://mobile_base_description/meshes/3d_depth_camera.dae"/>
      </geometry>
    </visual>
    <collision>
      <origin rpy="0 0 0" xyz="0 0 0"/>
      <geometry>
        <mesh filename="package://mobile_base_description/meshes/3d_depth_camera.stl"/>
      </geometry>
    </collision>
    <inertial>
      <mass value="0.3"/>
      <inertia ixx="0.0007031250000000001" ixy="0.0" ixz="0.0" iyy="6.25e-05" iyz="0.0" izz="0.000720625"/>
    </inertial>
  </link>
  <!-- Source: https://answers.ros.org/question/232534/gazebo-camera-frame-is-inconsistent-with-rviz-opencv-convention/ 
    These values have to be these, becuse otherwise the gazebo camera image won't be 
    aligned properly with the frame it is supposedly originating from.-->
  <joint name="camera_optical_joint" type="fixed">
    <origin rpy="-1.5707963267948966 0 -1.5707963267948966" xyz="0 0 0"/>
    <parent link="depth_camera_link"/>
    <child link="camera_link_optical"/>
  </joint>
  <link name="camera_link_optical">  
    </link>
  <joint name="front_bumper_joint" type="fixed">
    <parent link="base_link"/>
    <child link="front_bumper_link"/>
    <origin rpy="0 0 0" xyz="0.44 0 0.055"/>
  </joint>
  <link name="front_bumper_link">
    <visual>
      <origin rpy="0 0 0" xyz="0 0 0"/>
      <geometry>
        <mesh filename="package://mobile_base_description/meshes/bumper.dae"/>
      </geometry>
    </visual>
    <collision>
      <origin rpy="0 0 0" xyz="0 0 0"/>
      <geometry>
        <mesh filename="package://mobile_base_description/meshes/bumper.stl"/>
      </geometry>
    </collision>
    <inertial>
      <mass value="1.0"/>
      <inertia ixx="0.02381676333333333" ixy="0.0" ixz="0.0" iyy="0.002004513333333333" iyz="0.0" izz="0.02571375"/>
    </inertial>
  </link>
  <joint name="rear_bumper_joint" type="fixed">
    <parent link="base_link"/>
    <child link="rear_bumper_link"/>
    <origin rpy="0 0 3.141592653589793" xyz="-0.44 0 0.055"/>
  </joint>
  <link name="rear_bumper_link">
    <visual>
      <origin rpy="0 0 0" xyz="0 0 0"/>
      <geometry>
        <mesh filename="package://mobile_base_description/meshes/bumper.dae"/>
      </geometry>
    </visual>
    <collision>
      <origin rpy="0 0 0" xyz="0 0 0"/>
      <geometry>
        <mesh filename="package://mobile_base_description/meshes/bumper.stl"/>
      </geometry>
    </collision>
    <inertial>
      <mass value="1.0"/>
      <inertia ixx="0.02381676333333333" ixy="0.0" ixz="0.0" iyy="0.002004513333333333" iyz="0.0" izz="0.02571375"/>
    </inertial>
  </link>
</robot>
