<?xml version="1.0" ?>
<!-- =================================================================================== -->
<!-- |    This document was autogenerated by xacro from manip_robot.urdf.xacro         | -->
<!-- |    EDITING THIS FILE BY HAND IS NOT RECOMMENDED                                 | -->
<!-- =================================================================================== -->
<robot name="ur16e_manipulator_robot">
  <!-- Color Definitions for Rviz -->
  <material name="burlywood">
    <color rgba="0.87 0.72 0.53 1.0"/>
  </material>
  <material name="dark_blue">
    <color rgba="0.0 0.0 0.7 1.0"/>
  </material>
  <material name="light_blue">
    <color rgba="0.0 0.3 1.0 1.0"/>
  </material>
  <material name="sky_blue">
    <color rgba="0.1568627450980392 0.6549019607843137 0.9176470588235294 1.0"/>
  </material>
  <material name="light_green">
    <color rgba="0.0 1.0 0.0 1.0"/>
  </material>
  <material name="red">
    <color rgba="1.0 0.0 0.0 1.0"/>
  </material>
  <material name="orange">
    <color rgba="1.0 0.6 0.0 1.0"/>
  </material>
  <material name="yellow">
    <color rgba="1.0 1.0 0.0 1.0"/>
  </material>
  <material name="black">
    <color rgba="0.0 0.0 0.0 1.0"/>
  </material>
  <material name="white">
    <color rgba="1.0 1.0 1.0 1.0"/>
  </material>
  <material name="dark_gray">
    <color rgba="0.4 0.4 0.4 1.0"/>
  </material>
  <material name="light_gray">
    <color rgba="0.7 0.7 0.7 1.0"/>
  </material>
  <material name="plexiglass">
    <color rgba="1.0 1.0 1.0 0.2"/>
  </material>
  <material name="transparent">
    <color rgba="1.0 1.0 1.0 0.0"/>
  </material>
  <!-- Properties -->
  <!-- <xacro:property name="type" value="continuous"/> -->
  <!-- <xacro:include filename="$(find manip_description)/urdf/manip_gazebo.xacro" /> -->
  <link name="world_link">
    <origin rpy="0 0 0" xyz="0 0 0"/>
  </link>
  <joint name="arm_base_joint" type="continuous">
    <axis xyz="0 0 1"/>
    <parent link="world_link"/>
    <child link="arm_base_link"/>
    <!-- <limit lower="-3.14" upper="3.14" effort="1000.0" velocity="0.5"/> -->
    <origin rpy="0 0 0" xyz="0 0 0"/>
  </joint>
  <!--################################## Link ##################################-->
  <link name="arm_base_link">
    <visual>
      <origin rpy="0 0 0" xyz="0 0 0"/>
      <geometry>
        <mesh filename="package://manip_description/meshes/arm_base.stl"/>
      </geometry>
      <material name="sky_blue"/>
    </visual>
    <collision>
      <origin rpy="0 0 0" xyz="0 0 0"/>
      <geometry>
        <mesh filename="package://manip_description/meshes/arm_base.stl"/>
      </geometry>
    </collision>
    <inertial>
      <origin rpy="0 0 0" xyz="7.7128E-09 -0.063005 -3.01969999961422E-08"/>
      <mass value="1.6004"/>
      <inertia ixx="0.00552196561445819" ixy="7.9550614501301e-10" ixz="-1.34378458924839e-09" iyy="0.00352397447953875" iyz="-1.10071809773382e-08" izz="0.00553739792746489"/>
    </inertial>
  </link>
  <joint name="bicep_joint" type="continuous">
    <axis xyz="0 1 0"/>
    <parent link="arm_base_link"/>
    <child link="bicep_link"/>
    <!-- <limit lower="-3.14" upper="3.14" effort="1000.0" velocity="0.5"/> -->
    <origin rpy="0 0 1.5708" xyz="-0.05166 0.0 0.20271"/>
  </joint>
  <!--################################## Link ##################################-->
  <link name="bicep_link">
    <visual>
      <origin rpy="0 -1.5708 0" xyz="0 0 0"/>
      <geometry>
        <mesh filename="package://manip_description/meshes/bicep.stl"/>
      </geometry>
      <material name="light_gray"/>
    </visual>
    <collision>
      <origin rpy="0 -1.5708 0" xyz="0 0 0"/>
      <geometry>
        <mesh filename="package://manip_description/meshes/bicep.stl"/>
      </geometry>
    </collision>
    <inertial>
      <origin rpy="0 0 0" xyz="0.12821 3.5589E-06 0.052492"/>
      <mass value="1.1198"/>
      <inertia ixx="0.0012474" ixy="-5.4004e-07" ixz="-0.0013148" iyy="0.0072923" iyz="-1.8586e-07" izz="0.0068178"/>
    </inertial>
  </link>
  <joint name="bottom_wrist_joint" type="continuous">
    <axis xyz="0 1 0"/>
    <parent link="bicep_link"/>
    <child link="bottom_wrist_link"/>
    <!-- <limit lower="-3.14" upper="3.14" effort="1000.0" velocity="0.5"/> -->
    <origin rpy="0 0 0" xyz="0.0 -0.05194 0.269"/>
  </joint>
  <!--################################## Link ##################################-->
  <link name="bottom_wrist_link">
    <visual>
      <origin rpy="3.14 0 1.5708" xyz="0 0 0.13522"/>
      <geometry>
        <mesh filename="package://manip_description/meshes/wrist.stl"/>
      </geometry>
      <material name="sky_blue"/>
    </visual>
    <collision>
      <origin rpy="3.14 0 1.5708" xyz="0 0 0.13522"/>
      <geometry>
        <mesh filename="package://manip_description/meshes/wrist.stl"/>
      </geometry>
    </collision>
    <inertial>
      <origin rpy="0 0 0" xyz="9.1053E-08 -0.069257 -1.86629999995759E-07"/>
      <mass value="0.27721"/>
      <inertia ixx="0.00104290750143942" ixy="4.37155302268076e-09" ixz="-2.45049603914627e-09" iyy="0.000380518373895034" iyz="-7.56009835172156e-09" izz="0.00106006525067445"/>
    </inertial>
  </link>
  <joint name="elbow_joint" type="fixed">
    <parent link="bottom_wrist_link"/>
    <child link="elbow_link"/>
    <origin rpy="0 0 0" xyz="0.0 0 0.13522"/>
  </joint>
  <!--################################## Link ##################################-->
  <link name="elbow_link">
    <visual>
      <origin rpy="0 -1.5708 0" xyz="0.0 0.05163 0.20994"/>
      <geometry>
        <mesh filename="package://manip_description/meshes/elbow.stl"/>
      </geometry>
      <material name="light_gray"/>
    </visual>
    <collision>
      <origin rpy="0 -1.5708 0" xyz="0.0 0.05163 0.20994"/>
      <geometry>
        <mesh filename="package://manip_description/meshes/elbow.stl"/>
      </geometry>
    </collision>
    <inertial>
      <origin rpy="0 0 0" xyz="-0.11109 1.1476E-08 0.046469"/>
      <mass value="0.84845"/>
      <inertia ixx="0.00079656" ixy="-7.8011e-10" ixz="0.00053616" iyy="0.003576" iyz="4.6326e-10" izz="0.0033698"/>
    </inertial>
  </link>
  <joint name="top_wrist_joint" type="continuous">
    <axis xyz="0 1 0"/>
    <parent link="elbow_link"/>
    <child link="top_wrist_link"/>
    <!-- <limit lower="-3.14" upper="3.14" effort="1000.0" velocity="0.5"/> -->
    <origin rpy="0 0 0" xyz="0.0 0 0.20994"/>
  </joint>
  <!--################################## Link ##################################-->
  <link name="top_wrist_link">
    <visual>
      <origin rpy="3.14 0 1.5708" xyz="0 0 0.13522"/>
      <geometry>
        <mesh filename="package://manip_description/meshes/wrist.stl"/>
      </geometry>
      <material name="sky_blue"/>
    </visual>
    <collision>
      <origin rpy="3.14 0 1.5708" xyz="0 0 0.13522"/>
      <geometry>
        <mesh filename="package://manip_description/meshes/wrist.stl"/>
      </geometry>
    </collision>
    <inertial>
      <origin rpy="0 0 0" xyz="-9.1053E-08 -0.069257 -1.86629999995759E-07"/>
      <mass value="0.27721"/>
      <inertia ixx="0.00104290750143942" ixy="4.37155302268076e-09" ixz="-2.45049603914627e-09" iyy="0.000380518373895034" iyz="-7.56009835172156e-09" izz="0.00106006525067445"/>
    </inertial>
  </link>
  <!-- Based on https://github.com/a-price/robotiq_arg85_description/tree/master -->
  <!--############################### robotiq_arg85_base_link #################################-->
  <joint name="arm_to_gripper_joint" type="continuous">
    <origin rpy="0 0 0" xyz="0 0 0.135"/>
    <parent link="top_wrist_link"/>
    <child link="robotiq_arg85_base_link"/>
    <axis xyz="0 0 1"/>
    <!-- <limit lower="0" upper="0.725" velocity="2.0" effort="1000" /> -->
  </joint>
  <link name="robotiq_arg85_base_link">
    <inertial>
      <origin rpy="0 0 0" xyz="0.00021987 -2.3546E-10 0.030163"/>
      <mass value="0.30915"/>
      <inertia ixx="0.00028972" ixy="-5.7879E-10" ixz="-1.8543E-06" iyy="0.00030737" iyz="1.682E-12" izz="0.00019914"/>
    </inertial>
    <visual>
      <origin rpy="0 0 0" xyz="0 0 0"/>
      <geometry>
        <mesh filename="package://manip_description/meshes/gripper/robotiq_85_base_link_fine.STL"/>
      </geometry>
      <material name="">
        <color rgba="0.1 0.1 0.1 1"/>
      </material>
    </visual>
    <collision>
      <origin rpy="0 0 0" xyz="0 0 0"/>
      <geometry>
        <mesh filename="package://manip_description/meshes/gripper/robotiq_85_base_link_coarse.STL"/>
      </geometry>
    </collision>
  </link>
  <!--############################### left_outer_knuckle #################################-->
  <link name="left_outer_knuckle">
    <inertial>
      <origin rpy="0 0 0" xyz="0.0178331863169983 3.68915177224286E-11 0.0021442477325704"/>
      <mass value="0.00684838849434396"/>
      <inertia ixx="2.66832029033166E-07" ixy="1.66142314639824E-15" ixz="1.45945633322873E-07" iyy="1.3889233257419E-06" iyz="2.82951161241588E-15" izz="1.26603336914415E-06"/>
    </inertial>
    <visual>
      <origin rpy="0 0 0" xyz="0 0 0"/>
      <geometry>
        <mesh filename="package://manip_description/meshes/gripper/outer_knuckle_fine.STL"/>
      </geometry>
      <material name="">
        <color rgba="0.1 0.1 0.1 1"/>
      </material>
    </visual>
    <collision>
      <origin rpy="0 0 0" xyz="0 0 0"/>
      <geometry>
        <mesh filename="package://manip_description/meshes/gripper/outer_knuckle_coarse.STL"/>
      </geometry>
    </collision>
  </link>
  <joint name="finger_joint" type="revolute">
    <origin rpy="0 0 0" xyz="0.0306011444260539 0 0.0627920162695395"/>
    <parent link="robotiq_arg85_base_link"/>
    <child link="left_outer_knuckle"/>
    <axis xyz="0 -1 0"/>
    <limit effort="1000" lower="0" upper="0.725" velocity="2.0"/>
  </joint>
  <!--############################### left_outer_finger #################################-->
  <link name="left_outer_finger">
    <inertial>
      <origin rpy="0 0 0" xyz="0.00131451599174296 2.88942057994543E-15 0.0215404163180413"/>
      <mass value="0.0273093985570947"/>
      <inertia ixx="8.51629628283022E-06" ixy="2.58174336207405E-19" ixz="3.83829504344079E-07" iyy="6.9133328065108E-06" iyz="-7.58589926143789E-19" izz="2.25006832221981E-06"/>
    </inertial>
    <visual>
      <origin rpy="0 0 0" xyz="0 0 0"/>
      <geometry>
        <mesh filename="package://manip_description/meshes/gripper/outer_finger_fine.STL"/>
      </geometry>
      <material name="">
        <color rgba="0.1 0.1 0.1 1"/>
      </material>
    </visual>
    <collision>
      <origin rpy="0 0 0" xyz="0 0 0"/>
      <geometry>
        <mesh filename="package://manip_description/meshes/gripper/outer_finger_coarse.STL"/>
      </geometry>
    </collision>
  </link>
  <joint name="left_outer_finger_joint" type="fixed">
    <origin rpy="0 0 0" xyz="0.0316910442266543 0 -0.00193396375724605"/>
    <parent link="left_outer_knuckle"/>
    <child link="left_outer_finger"/>
    <axis xyz="0 -1 0"/>
  </joint>
  <!--############################### left_inner_knuckle #################################-->
  <link name="left_inner_knuckle">
    <inertial>
      <origin rpy="0 0 0" xyz="0.017097546626628 -3.93808524389535E-10 0.0224918438201868"/>
      <mass value="0.0110930853895903"/>
      <inertia ixx="4.23392770691541E-06" ixy="5.748978936968E-15" ixz="1.78855677119788E-06" iyy="3.96548790524392E-06" iyz="1.05464666369669E-14" izz="3.24068002883007E-06"/>
    </inertial>
    <visual>
      <origin rpy="0 0 0" xyz="0 0 0"/>
      <geometry>
        <mesh filename="package://manip_description/meshes/gripper/inner_knuckle_fine.STL"/>
      </geometry>
      <material name="">
        <color rgba="0.1 0.1 0.1 1"/>
      </material>
    </visual>
    <collision>
      <origin rpy="0 0 0" xyz="0 0 0"/>
      <geometry>
        <mesh filename="package://manip_description/meshes/gripper/inner_knuckle_coarse.STL"/>
      </geometry>
    </collision>
  </link>
  <joint name="left_inner_knuckle_joint" type="revolute">
    <origin rpy="0 0 0" xyz="0.0127000000001501 0 0.0693074999999639"/>
    <parent link="robotiq_arg85_base_link"/>
    <child link="left_inner_knuckle"/>
    <axis xyz="0 -1 0"/>
    <limit effort="1000" lower="0" upper="0.8757" velocity="2.0"/>
    <mimic joint="finger_joint" multiplier="1" offset="0"/>
  </joint>
  <!--############################### left_inner_finger #################################-->
  <link name="left_inner_finger">
    <inertial>
      <origin rpy="0 0 0" xyz="0.0060275613594574 -6.29183141465421E-15 0.00669925693133241"/>
      <mass value="0.00724255346165745"/>
      <inertia ixx="1.47824274053603E-06" ixy="-3.94884463570303E-19" ixz="-3.45268847648622E-07" iyy="1.70064480838395E-06" iyz="3.5059838910097E-19" izz="4.77151336838364E-07"/>
    </inertial>
    <visual>
      <origin rpy="0 0 0" xyz="0 0 0"/>
      <geometry>
        <mesh filename="package://manip_description/meshes/gripper/inner_finger_fine.STL"/>
      </geometry>
      <material name="">
        <color rgba="0.1 0.1 0.1 1"/>
      </material>
    </visual>
    <collision>
      <origin rpy="0 0 0" xyz="0 0 0"/>
      <geometry>
        <mesh filename="package://manip_description/meshes/gripper/inner_finger_coarse.STL"/>
      </geometry>
    </collision>
  </link>
  <joint name="left_inner_finger_joint" type="revolute">
    <origin rpy="0 0 0" xyz="0.034585310861294 0 0.0454970193817975"/>
    <parent link="left_inner_knuckle"/>
    <child link="left_inner_finger"/>
    <axis xyz="0 -1 0"/>
    <limit effort="1000" lower="0" upper="0.8757" velocity="2.0"/>
    <mimic joint="finger_joint" multiplier="-1" offset="0"/>
  </joint>
  <!--############################### right_inner_knuckle #################################-->
  <link name="right_inner_knuckle">
    <inertial>
      <origin rpy="0 0 0" xyz="0.0168606186773776 3.93808471820465E-10 0.0226699950793434"/>
      <mass value="0.0110930853895903"/>
      <inertia ixx="4.27134775939882E-06" ixy="-8.53568456728898E-15" ixz="1.77774229944246E-06" iyy="3.96548790524392E-06" iyz="-8.45108024914164E-15" izz="3.20325997634666E-06"/>
    </inertial>
    <visual>
      <origin rpy="0 0 0" xyz="0 0 0"/>
      <geometry>
        <mesh filename="package://manip_description/meshes/gripper/inner_knuckle_fine.STL"/>
      </geometry>
      <material name="">
        <color rgba="0.1 0.1 0.1 1"/>
      </material>
    </visual>
    <collision>
      <origin rpy="0 0 0" xyz="0 0 0"/>
      <geometry>
        <mesh filename="package://manip_description/meshes/gripper/inner_knuckle_coarse.STL"/>
      </geometry>
    </collision>
  </link>
  <joint name="right_inner_knuckle_joint" type="revolute">
    <origin rpy="0 0 3.14159265358979" xyz="-0.0126999999998499 0 0.0693075000000361"/>
    <parent link="robotiq_arg85_base_link"/>
    <child link="right_inner_knuckle"/>
    <axis xyz="0 1 0"/>
    <limit effort="1000" lower="0" upper="0.8757" velocity="2.0"/>
    <mimic joint="finger_joint" multiplier="-1" offset="0"/>
  </joint>
  <!--############################### right_inner_finger #################################-->
  <link name="right_inner_finger">
    <inertial>
      <origin rpy="0 0 0" xyz="0.00602756228812038 -6.47284509480176E-15 0.00669925609578108"/>
      <mass value="0.00724255346165744"/>
      <inertia ixx="1.47824283625957E-06" ixy="-3.95952064019123E-19" ixz="-3.45268708875543E-07" iyy="1.70064480838394E-06" iyz="3.55286507960029E-19" izz="4.77151241114822E-07"/>
    </inertial>
    <visual>
      <origin rpy="0 0 0" xyz="0 0 0"/>
      <geometry>
        <mesh filename="package://manip_description/meshes/gripper/inner_finger_fine.STL"/>
      </geometry>
      <material name="">
        <color rgba="0.1 0.1 0.1 1"/>
      </material>
    </visual>
    <collision>
      <origin rpy="0 0 0" xyz="0 0 0"/>
      <geometry>
        <mesh filename="package://manip_description/meshes/gripper/inner_finger_coarse.STL"/>
      </geometry>
    </collision>
  </link>
  <joint name="right_inner_finger_joint" type="revolute">
    <origin rpy="0 0 0" xyz="0.0341060475457406 0 0.0458573878541688"/>
    <parent link="right_inner_knuckle"/>
    <child link="right_inner_finger"/>
    <axis xyz="0 1 0"/>
    <limit effort="1000" lower="0" upper="0.8757" velocity="2.0"/>
    <mimic joint="finger_joint" multiplier="1" offset="0"/>
  </joint>
  <!--############################### right_outer_knuckle #################################-->
  <link name="right_outer_knuckle">
    <inertial>
      <origin rpy="0 0 0" xyz="0.0178097074051638 3.60493211424024E-11 0.00233123458346721"/>
      <mass value="0.00684838849401352"/>
      <inertia ixx="2.70004361573169E-07" ixy="1.59579467624491E-15" ixz="1.56396493788199E-07" iyy="1.38892332558312E-06" iyz="2.82357800318817E-15" izz="1.26286103637978E-06"/>
    </inertial>
    <visual>
      <origin rpy="0 0 0" xyz="0 0 0"/>
      <geometry>
        <mesh filename="package://manip_description/meshes/gripper/outer_knuckle_fine.STL"/>
      </geometry>
      <material name="">
        <color rgba="0.1 0.1 0.1 1"/>
      </material>
    </visual>
    <collision>
      <origin rpy="0 0 0" xyz="0 0 0"/>
      <geometry>
        <mesh filename="package://manip_description/meshes/gripper/outer_knuckle_coarse.STL"/>
      </geometry>
    </collision>
  </link>
  <joint name="right_outer_knuckle_joint" type="revolute">
    <origin rpy="0 0 3.14159265358979" xyz="-0.0306011444258893 0 0.0627920162695395"/>
    <parent link="robotiq_arg85_base_link"/>
    <child link="right_outer_knuckle"/>
    <axis xyz="0 1 0"/>
    <limit effort="1000" lower="0" upper="0.8757" velocity="2.0"/>
    <mimic joint="finger_joint" multiplier="-1" offset="0"/>
  </joint>
  <!--############################### right_outer_finger #################################-->
  <link name="right_outer_finger">
    <inertial>
      <origin rpy="0 0 0" xyz="0.00108844269639009 -2.611488350845E-15 0.0215530225245502"/>
      <mass value="0.0273093985570947"/>
      <inertia ixx="8.52366028592721E-06" ixy="3.41683380899422E-19" ixz="3.18003675694284E-07" iyy="6.91333280651081E-06" iyz="7.37726682706417E-19" izz="2.24270431912283E-06"/>
    </inertial>
    <visual>
      <origin rpy="0 0 0" xyz="0 0 0"/>
      <geometry>
        <mesh filename="package://manip_description/meshes/gripper/outer_finger_fine.STL"/>
      </geometry>
      <material name="">
        <color rgba="0.1 0.1 0.1 1"/>
      </material>
    </visual>
    <collision>
      <origin rpy="0 0 0" xyz="0 0 0"/>
      <geometry>
        <mesh filename="package://manip_description/meshes/gripper/outer_finger_coarse.STL"/>
      </geometry>
    </collision>
  </link>
  <joint name="right_outer_finger_joint" type="fixed">
    <origin rpy="0 0 0" xyz="0.0317095909367246 0 -0.0016013564954687"/>
    <parent link="right_outer_knuckle"/>
    <child link="right_outer_finger"/>
    <axis xyz="0 1 0"/>
  </joint>
</robot>
